Workbook

Sheet ACF Scores
A1: Run | B1: Model | C1: Category | D1: Question | E1: Ground Truth | F1: Response | G1: Rouge-L IU Recall | H1: BERT IU Recall | I1: BERT Precision | J1: BERT Recall | K1: BERT F1 | L1: Completeness | M1: SBERT | N1: Accuracy | O1: Similarity Score | P1: Readability Score
A2: Run 2 | B2: ChatGPT 5.2 Extended Thinking | C2: How (global) | D2: What kind of algorithm is used? | E2: The algorithm is a hyperparameter tuned XGBoost classifier model used to generate predictions. This is an ensemble method using many individual decision trees, sequentially learning from the previous one. | F2: The deployed model is an XGBoost classifier, which is an ensemble of gradient-boosted decision trees. In practical terms, it combines many simple decision rules into a single probability estimate and can capture non-linear relationships and interactions between factors. | G2: 1 | H2: 0.914 | I2: 0.891 | J2: 0.896 | K2: 0.893 | L2: =(G2+H2)/2 -> 0.957 | M2: 0.74 | N2: 1 | O2: =(N2+M2+(G2+H2)/2)/3 -> 0.899 | P2: {=INDEX('Readability Avg Scores'!E:E,MATCH(1,('ACF Scores'!B2 = 'Readability Avg Scores'!A:A)*('ACF Scores'!D2='Readability Avg Scores'!C:C),0))} -> 15.76425
A3: Run 2 | B3: ChatGPT 5.2 Extended Thinking | C3: Data | D3: What is the source of the training data? | E3: Data is sourced from DrivenData's 'Flu Shot Learning: Predict H1N1 and Seasonal Flu Vaccines' competition and originates from the US National 2009 H1N1 Flu Survey (NHFS). This survey was conducted between October 2009 and June 2010 as a one-time telephone survey of households to monitor vaccinations during the 2009-2010 flu season in response to the 2009 H1N1 pandemic. | F3: The training data come from the National 2009 H1N1 Flu Survey (NHFS), a list-assisted random-digit-dialling telephone survey conducted between October 2009 and June 2010. The NHFS was sponsored by the National Center for Immunization and Respiratory Diseases and conducted jointly with the National Center for Health Statistics at the US Centers for Disease Control and Prevention. The dataset was distributed via the “Flu Shot Learning” competition hosted by DrivenData. | G3: 0.73 | H3: 0.9 | I3: 0.874 | J3: 0.903 | K3: 0.888 | L3: =(G3+H3)/2 -> 0.815 | M3: 0.879 | N3: 1 | O3: =(N3+M3+(G3+H3)/2)/3 -> 0.898 | P3: {=INDEX('Readability Avg Scores'!E:E,MATCH(1,('ACF Scores'!B3 = 'Readability Avg Scores'!A:A)*('ACF Scores'!D3='Readability Avg Scores'!C:C),0))} -> 15.17675
A4: Run 2 | B4: ChatGPT 5.2 Extended Thinking | C4: How (global) | D4: What are the top rules/features that determine its predictions? | E4: There are three features which are significantly more influential than others. These are: if the doctor recommends the H1N1 vaccine (doctor_recc_h1n1), how much of a risk the individual considers the H1N1 virus (opinion_h1n1_risk), and if the individual believes the vaccine is effective (opinion_h1n1_vacc_effective). This means an observation is more likely to get the vaccine if a doctor recommends the vaccine, they view the H1N1 as a high risk, and they believe the H1N1 vaccine is effective. | F4: Global variable-importance results indicate the strongest drivers include whether a doctor recommended the H1N1 vaccine, belief that the H1N1 vaccine is effective, and perceived risk from H1N1. Other influential factors include being a health worker and age group, followed by variables such as employment industry, level of H1N1 concern, geographic region, and worry about becoming sick from the vaccine. These factors should be interpreted as influential predictors in the survey data, not as causal determinants. | G4: 0.889 | H4: 0.893 | I4: 0.87 | J4: 0.87 | K4: 0.87 | L4: =(G4+H4)/2 -> 0.891 | M4: 0.76 | N4: 1 | O4: =(N4+M4+(G4+H4)/2)/3 -> 0.88366667 | P4: {=INDEX('Readability Avg Scores'!E:E,MATCH(1,('ACF Scores'!B4 = 'Readability Avg Scores'!A:A)*('ACF Scores'!D4='Readability Avg Scores'!C:C),0))} -> 15.122
A5: Run 2 | B5: ChatGPT 5.2 Extended Thinking | C5: Output | D5: What is the source of the information object(s)? | E5: The information objects are the predictions and explanation interface (i.e. What-If? dashboard). These predictions are generated from a XGBoost classifier model which has been hyperparameter tuned and trained on protected (e.g. sex, age, education, employment), behavioural (e.g. social distancing, mask wearing, hand washing), opinion (H1N1 concern, doctor vaccine recommendation), health (e.g. chronic medial conditions, health insurance) and sociodemographic (e.g. geographical region, employment industry) characteristics from the National 2009 H1N1 Flu Survey (NHFS) data. The explanation interface is produced from DALEX, which uses the XGBoost classifier model and its training/testing data. This produces an explanation object which creates global (AUC_ROC, feature importance, partial dependence, accumulated local effects) and local (breakdown, Shapley values, ceteris paribus) explanations. | F5: Predicted probabilities and classifications are produced by a trained XGBoost classifier applied to the provided feature values after preprocessing (imputation and one-hot encoding). The explanation objects (variable importance, breakdown, Shapley values, and ceteris paribus profiles) are generated by the DALEX explainer using the trained model together with the held-out test dataset as the reference. | G5: 1 | H5: 0.896 | I5: 0.873 | J5: 0.831 | K5: 0.851 | L5: =(G5+H5)/2 -> 0.948 | M5: 0.695 | N5: 1 | O5: =(N5+M5+(G5+H5)/2)/3 -> 0.881 | P5: {=INDEX('Readability Avg Scores'!E:E,MATCH(1,('ACF Scores'!B5 = 'Readability Avg Scores'!A:A)*('ACF Scores'!D5='Readability Avg Scores'!C:C),0))} -> 18.07275
A6: Run 2 | B6: ChatGPT 5.2 Extended Thinking | C6: Others | D6: Who is responsible for this system? Who are the authors? | E6: Henry El-Jawhari is the author and developed this AI system in conjunction with the Freie Universität Berlin and Robert Koch Institute. | F6: The system was developed by Henry El-Jawhari at the Freie Universität (FU) Berlin and the Robert Koch Institute (RKI). No additional organisational owner, clinical sponsor, or regulatory responsible party is specified in the available materials. | G6: 1 | H6: 0.92 | I6: 0.88 | J6: 0.946 | K6: 0.912 | L6: =(G6+H6)/2 -> 0.96 | M6: 0.577 | N6: 1 | O6: =(N6+M6+(G6+H6)/2)/3 -> 0.84566667 | P6: {=INDEX('Readability Avg Scores'!E:E,MATCH(1,('ACF Scores'!B6 = 'Readability Avg Scores'!A:A)*('ACF Scores'!D6='Readability Avg Scores'!C:C),0))} -> 15.668
A7: Run 2 | B7: ChatGPT 5.2 Extended Thinking | C7: How (global) | D7: How does the system make predictions? | E7: The system makes predictions using a hyperparameter tuned XGBoost classifier model. This produces a predicted probability on the interval [0, 1]. | F7: The system preprocesses inputs by imputing missing values and one-hot encoding categorical variables, then applies a gradient-boosted decision-tree model (XGBoost) to estimate a probability of H1N1 vaccination. The probability can be thresholded to produce a Yes/No prediction. Explanation modules can then attribute how individual inputs contributed to the prediction for review. | G7: 1 | H7: 0.914 | I7: 0.846 | J7: 0.882 | K7: 0.864 | L7: =(G7+H7)/2 -> 0.957 | M7: 0.535 | N7: 1 | O7: =(N7+M7+(G7+H7)/2)/3 -> 0.83066667 | P7: {=INDEX('Readability Avg Scores'!E:E,MATCH(1,('ACF Scores'!B7 = 'Readability Avg Scores'!A:A)*('ACF Scores'!D7='Readability Avg Scores'!C:C),0))} -> 16.92475
A8: Run 2 | B8: ChatGPT 5.2 Extended Thinking | C8: Performance | D8: How often does the system make mistakes? | E8: The system has an accuracy of 0.84 (i.e. 84% of observations were correctly classified). This means the system makes mistakes 16% of the time. | F8: On the 5,342-person test set, there were 856 misclassifications (about 16%). These errors comprised 250 false positives (predicting vaccination when the person was not vaccinated) and 606 false negatives (missing a true vaccinated case). The error pattern is therefore dominated by missed vaccinated cases at the default threshold. | G8: 1 | H8: 0.84 | I8: 0.847 | J8: 0.879 | K8: 0.863 | L8: =(G8+H8)/2 -> 0.92 | M8: 0.558 | N8: 1 | O8: =(N8+M8+(G8+H8)/2)/3 -> 0.826 | P8: {=INDEX('Readability Avg Scores'!E:E,MATCH(1,('ACF Scores'!B8 = 'Readability Avg Scores'!A:A)*('ACF Scores'!D8='Readability Avg Scores'!C:C),0))} -> 13.05925
A9: Run 2 | B9: ChatGPT 5.2 Extended Thinking | C9: Performance | D9: How accurate/precise/reliable are the predictions? | E9: Key performance metrics for the XGBoost classifier model are: Recall = 0.464, Precision = 0.677, F1 = 0.55, Accuracy = 0.84, AUC = 0.838. This means the system is good at identifying if an observation will receive the H1N1 vaccination or not. | F9: On the held-out test set, the model achieved an accuracy of 0.84 and an AUC of 0.838. For identifying vaccinated individuals, precision was 0.677 and recall (sensitivity) was 0.464, with an F1 score of 0.55. This means the system is substantially better at identifying non-vaccination than at reliably finding all true vaccinators at the default threshold. | G9: 1 | H9: 0.888 | I9: 0.894 | J9: 0.893 | K9: 0.893 | L9: =(G9+H9)/2 -> 0.944 | M9: 0.515 | N9: 1 | O9: =(N9+M9+(G9+H9)/2)/3 -> 0.81966667 | P9: {=INDEX('Readability Avg Scores'!E:E,MATCH(1,('ACF Scores'!B9 = 'Readability Avg Scores'!A:A)*('ACF Scores'!D9='Readability Avg Scores'!C:C),0))} -> 10.67475
A10: Run 2 | B10: ChatGPT 5.2 Extended Thinking | C10: How (global) | D10: What features does the system consider? | E10: The system considers a range of features including protected (e.g. sex, age, education, employment), behavioural (e.g. social distancing, mask wearing, hand washing), opinion (H1N1 concern, doctor vaccine recommendation), health (e.g. chronic medial conditions, health insurance) and sociodemographic (e.g. geographical region, employment industry) characteristics collected from the US National 2009 H1N1 Flu Survey (NHFS). | F10: The model uses a mix of behavioural variables (e.g., avoidance behaviours, mask use, hand washing), opinion/risk perception variables (e.g., perceived H1N1 risk, belief that the vaccine is effective, worry about getting sick from the vaccine, and whether a doctor recommended vaccination), and health factors (e.g., chronic medical condition, insurance, health-worker status, having a child under 6 months). It also includes demographic and socio-economic characteristics such as age group, sex, race, education, income poverty category, marital status, housing, employment status, household adults/children, and location indicators (HHS region and census MSA). Seasonal flu-related variables are explicitly excluded. | G10: 0.6 | H10: 0.812 | I10: 0.862 | J10: 0.895 | K10: 0.878 | L10: =(G10+H10)/2 -> 0.706 | M10: 0.74 | N10: 1 | O10: =(N10+M10+(G10+H10)/2)/3 -> 0.81533333 | P10: {=INDEX('Readability Avg Scores'!E:E,MATCH(1,('ACF Scores'!B10 = 'Readability Avg Scores'!A:A)*('ACF Scores'!D10='Readability Avg Scores'!C:C),0))} -> 15.5045
A11: Run 2 | B11: ChatGPT 5.2 Extended Thinking | C11: UI | D11: What does this UI element do? | E11: Using the What-If? dashboard, the toggle buttons allow the user to select and change the most important characteristics an observation. A float slider allows the user to change the prediction threshold, making their predictions of H1N1 vaccine uptake more/less conservative. | F11: Toggle buttons set the value of a selected feature for the hypothetical individual being evaluated, and the threshold slider changes the probability cut-off used to convert the prediction into a Yes/No output. The “Run What-If? Dashboard” button executes the prediction with the chosen settings and refreshes the displayed probability, binary interpretation, and explanation/sensitivity plots. The output area is where the system prints the selected characteristics and summarises the prediction. | G11: 0.542 | H11: 0.855 | I11: 0.861 | J11: 0.88 | K11: 0.871 | L11: =(G11+H11)/2 -> 0.6985 | M11: 0.72 | N11: 1 | O11: =(N11+M11+(G11+H11)/2)/3 -> 0.80616667 | P11: {=INDEX('Readability Avg Scores'!E:E,MATCH(1,('ACF Scores'!B11 = 'Readability Avg Scores'!A:A)*('ACF Scores'!D11='Readability Avg Scores'!C:C),0))} -> 15.2775
A12: Run 2 | B12: ChatGPT 5.2 Extended Thinking | C12: Others | D12: Why is the system using or not using a given algorithm/feature/rule/dataset? | E12: Different algorithms were trained and tested for model selection. The XGBoost classifier model was chosen because it had the best performance for mean accuracy and ROC-AUC values compared to the Logistic Regression, Random Forest and Multi-layer Perceptron models. Feature selection was performed and the H1N1 vaccination status was chosen as the target variable in order to model the response to the H1N1 pandemic outbreak. Seasonal vaccination features were excluded to avoid any feature leakage, and no additional data was used to avoid introducing noise into the modelling process, which would unfairly or negatively effect model performance. Only data provided by the US National 2009 H1N1 Flu Survey (NHFS) was used. Imputations were made on missing values in order to use as much data as possible for training. | F12: Multiple baseline algorithms were tested (logistic regression, random forest, XGBoost, and a multilayer perceptron), and the hyperparameter-tuned XGBoost model was selected because it achieved the highest mean accuracy on the test set. Seasonal influenza-related variables were removed to avoid information leakage when predicting H1N1 uptake. The respondent identifier was excluded because it is only a unique ID and does not carry clinically meaningful information. | G12: 0.357 | H12: 0.859 | I12: 0.881 | J12: 0.868 | K12: 0.874 | L12: =(G12+H12)/2 -> 0.608 | M12: 0.804 | N12: 1 | O12: =(N12+M12+(G12+H12)/2)/3 -> 0.804 | P12: {=INDEX('Readability Avg Scores'!E:E,MATCH(1,('ACF Scores'!B12 = 'Readability Avg Scores'!A:A)*('ACF Scores'!D12='Readability Avg Scores'!C:C),0))} -> 16.9065
A13: Run 2 | B13: ChatGPT 5.2 Extended Thinking | C13: Others | D13: What are the results of other people using the system? | E13: There are no results of other people using the system. People can use and operate this system independently, with the results are isolated to their own instance. These results do not influence other users or how the system works, and they are not stored/shared in any capacity. | F13: No real-world usage results, external validations, or user studies are reported. The only reported results are the internal performance metrics on the held-out test split of the survey dataset. | G13: 1 | H13: 0.869 | I13: 0.855 | J13: 0.865 | K13: 0.86 | L13: =(G13+H13)/2 -> 0.9345 | M13: 0.472 | N13: 1 | O13: =(N13+M13+(G13+H13)/2)/3 -> 0.80216667 | P13: {=INDEX('Readability Avg Scores'!E:E,MATCH(1,('ACF Scores'!B13 = 'Readability Avg Scores'!A:A)*('ACF Scores'!D13='Readability Avg Scores'!C:C),0))} -> 13.25475
... A109: Run 1 | B109: Gemini 3 Pro | C109: How (global) | D109: What is the system's overall logic? | E109: The overall logic of the system is to generate individual level predictions for H1N1 vaccine uptake, and provide explanations through the What-If? dahsboard. Model performance is evaluated, and explanations are provided on both a global (model) and local (prediction) level. | F109: The model uses a gradient boosting framework, building multiple decision trees sequentially to correct the errors of previous trees. It combines the inputs non-linearly to calculate a probability score. | G109: 0 | H109: 0.853 | I109: 0.849 | J109: 0.84 | K109: 0.845 | L109: =(G109+H109)/2 -> 0.4265 | M109: 0.341 | N109: 0.5 | O109: =(N109+M109+(G109+H109)/2)/3 -> 0.4225 | P109: {=INDEX('Readability Avg Scores'!E:E,MATCH(1,('ACF Scores'!B109 = 'Readability Avg Scores'!A:A)*('ACF Scores'!D109='Readability Avg Scores'!C:C),0))} -> 14.49775

Sheet Readability Avg Scores
A1: Model | B1: Category | C1: Question | D1: Answer | E1: Readability Score
A2: Gemini 3 Pro | B2: Output | C2: What logic is used for the initial output/recommendation? | D2: The system applies a threshold of 0.5 to the predicted probability. If the probability is greater than or equal to 0.5, it predicts 'Yes' (1); otherwise, it predicts 'No' (0). | E2: 7.97025
A3: Gemini 3 Pro | B3: Others | C3: Does the system learn specifically from my interaction? | D3: No, the system does not learn from individual user interactions. It uses a pre-trained model saved in a `pickle` file. | E3: 8.82025
A4: Gemini 3 Pro | B4: Performance | C4: In what situations is the system likely to be correct/incorrect? | D4: The system is highly likely to be correct when predicting individuals who will *not* get the vaccine (Recall for class 0 is 0.94). It is much more likely to be incorrect when identifying those who *did* get the vaccine, missing more than half of them (Recall for class 1 is only 0.46). | E4: 9.9925
A5: ChatGPT 5.2 Extended Thinking | B5: Data | C5: What is the sample size of the training data? | D5: There are 26,707 respondents in the combined training dataset. For modelling, the data were split 80:20 into 21,365 training records and 5,342 test records. Model performance figures reported for the system are based on that held-out test set. | E5: 10.42475
A6: Gemini 3 Pro | B6: UI | C6: What does this UI element do? | D6: The toggle buttons (e.g., for `doctor_recc_h1n1` or `opinion_h1n1_risk`) allow the user to change the input values for a hypothetical patient profile. The float slider adjusts the decision threshold (default 0.5) to see how it affects the binary prediction. | E6: 10.61225
A7: ChatGPT 5.2 Extended Thinking | B7: Performance | C7: How accurate/precise/reliable are the predictions? | D7: On the held-out test set, the model achieved an accuracy of 0.84 and an AUC of 0.838. For identifying vaccinated individuals, precision was 0.677 and recall (sensitivity) was 0.464, with an F1 score of 0.55. This means the system is substantially better at identifying non-vaccination than at reliably finding all true vaccinators at the default threshold. | E7: 10.67475
A8: Gemini 3 Pro | B8: Performance | C8: How accurate/precise/reliable are the predictions? | D8: The system has an overall accuracy of 84%. However, for predicting the vaccinated class (class 1), the precision is 68% and recall is 46%, meaning it is more reliable when it predicts 'Yes' than it is at catching all 'Yes' cases. | E8: 10.74225
A9: Gemini 3 Pro | B9: UI | C9: What are the affordances of the system? | D9: The dashboard affords interaction through toggle buttons for categorical features (e.g., 'Doctor recommends H1N1 vaccine', 'Age Group') and a float slider for setting the prediction threshold. Users can click a 'Run What-If? Dashboard' button to update predictions. | E9: 11.13425
A10: Gemini 3 Pro | B10: Performance | C10: What are the limitations of the system? | D10: The primary limitation is its low sensitivity (recall) for the positive class. It identifies less than 50% of the people who actually got the vaccine. This means relying solely on the model to flag all vaccinated individuals would result in many missed cases. | E10: 11.33475
A11: Gemini 3 Pro | B11: Performance | C11: What kind of mistakes is the system likely to make? | D11: The system is prone to False Negatives (missed detections). It missed 606 true cases of vaccination in the test set, compared to only 250 False Positives (false alarms). Clinically, this means it is conservative in predicting vaccination uptake. | E11: 11.41575
A12: Gemini 3 Pro | B12: Output | C12: What is the scope of the output data? | D12: The output data is scoped to the individual level. The system generates a prediction for each single respondent or patient profile processed. | E12: 11.5145
A13: Gemini 3 Pro | B13: How (global model-wide explanation) | C13: What kind of rules does it follow? | D13: The system does not follow simple 'if-then' rules like a flowchart. Instead, it follows complex, non-linear patterns learned from the data, represented by thousands of decision paths in the XGBoost ensemble. | E13: 11.8065
... A109: Claude Opus 4.6 Reasoning | B109: UI | C109: What does this UI element do? | D109: The system's interface includes several key visual elements: variable importance bar charts display features ranked by their impact on model performance (measured by dropout loss — higher values indicate greater importance); partial dependence profile plots show how the average predicted probability changes as a single feature varies across its range, helping users understand the direction and magnitude of each feature's effect; accumulated local effects plots provide a similar view but account for correlations between features, offering a more robust interpretation; break-down plots decompose an individual prediction into positive and negative contributions from each feature, showing which factors pushed the prediction higher or lower; and the what-if dashboard presents an interactive scatter plot where users can select individual data points, modify their feature values, and observe real-time changes in predicted probabilities. | E109: 33.48275

Sheet Readability All Scores
A1: Model | B1: Category | C1: Question | D1: Answer | E1: Metric | F1: Score
A2: Gemini 3 Pro | B2: Data | C2: What kind of data was the system trained on? | D2: The system was trained on data from the National 2009 H1N1 Flu Survey (NHFS), which includes information about 26,707 individuals. The data consists of 35 features covering demographic characteristics (e.g., age, race, sex), socioeconomic status, opinions about H1N1 and vaccination (e.g., concern, knowledge, effectiveness), and behavioural traits (e.g., mask-wearing, hand washing). | E2: SMOG Index | F2: 11.208 | H2: {=_xlfn.UNIQUE(A:A)} -> Model
A3: Gemini 3 Pro | B3: Data | C3: What is the source of the training data? | D3: The data originates from the National 2009 H1N1 Flu Survey (NHFS), which was sponsored by the National Center for Immunization and Respiratory Diseases (NCIRD) and conducted jointly by the NCIRD and the National Center for Health Statistics (NCHS), Centers for Disease Control and Prevention (CDC). The specific dataset used was downloaded from DrivenData's 'Flu Shot Learning' competition. | E3: SMOG Index | F3: 18.244 | H3: Gemini 3 Pro | I3: =AVERAGEIF(A:A,H3,F:F) -> 13.755611 | J3: =I3-$I$6 -> 0.61122222
A4: Gemini 3 Pro | B4: Data | C4: How were the labels/ground-truth produced? | D4: The labels are based on self-reported survey responses from the National 2009 H1N1 Flu Survey, where respondents indicated whether they had received the H1N1 flu vaccine. This binary response (Yes/No) serves as the ground truth for training the model. | E4: SMOG Index | F4: 13.024 | H4: ChatGPT 5.2 Extended Thinking | I4: =AVERAGEIF(A:A,H4,F:F) -> 14.798625 | J4: =I4-$I$6 -> 1.6542361
A5: Gemini 3 Pro | B5: Data | C5: What is the sample size of the training data? | D5: The total dataset contains 26,707 observations. This was split into training and testing sets; the test set used for evaluating the model contains 5,342 rows, suggesting an approximate 80/20 split, leaving around 21,365 records for training. | E5: SMOG Index | F5: 11.208 | H5: Claude Opus 4.6 Reasoning | I5: =AVERAGEIF(A:A,H5,F:F) -> 16.713576 | J5: =I5-$I$6 -> 3.5691875
A6: Gemini 3 Pro | B6: Data | C6: What dataset(s) is the system NOT using? | D6: The system explicitly excludes the `seasonal_vaccine` variable (whether the respondent received the seasonal flu vaccine) and `respondent_id`. The `seasonal_vaccine` feature was removed to avoid feature leakage and ensure the model focuses solely on predicting H1N1 vaccine uptake based on other factors. | E6: SMOG Index | F6: 15.248 | H6: Human | I6: =AVERAGEIF(A:A,H6,F:F) -> 13.144389
A7: Gemini 3 Pro | B7: Data | C7: What are the potential limitations/biases of the data? | D7: The data is from a telephone survey (landline and mobile) conducted in 2009-2010, which may exclude populations without phone access or those less likely to participate in phone surveys. Additionally, as a self-reported survey, it is subject to recall bias or social desirability bias. The dataset is also specific to the United States context during the 2009 H1N1 pandemic, so patterns may not generalize to other regions or future pandemics. | E7: SMOG Index | F7: 14.068 | H7: 0
A8: Gemini 3 Pro | B8: Output | C8: What kind of output does the system give? | D8: The system outputs a probability (a score between 0 and 1) representing the likelihood that a specific individual received the H1N1 vaccine. It also provides a binary classification (0 for 'No', 1 for 'Yes') based on a threshold of 0.5. | E8: SMOG Index | F8: 13.817
A9: Gemini 3 Pro | B9: Output | C9: What does the system output mean? | D9: A binary output of '1' predicts that the patient is likely to have received the H1N1 vaccine, while '0' suggests they have not. The underlying probability score indicates the model's confidence in this prediction; a higher score suggests a higher likelihood of vaccination. | E9: SMOG Index | F9: 14.555
A10: Gemini 3 Pro | B10: Output | C10: What is the scope of the system's capability? Can it do...? | D10: The system is capable of predicting the H1N1 vaccine uptake status for an individual based on their demographic and behavioural data. It is strictly a classification model for this specific outcome and does not predict seasonal flu uptake or other health outcomes. | E10: SMOG Index | F10: 13.817
A11: Gemini 3 Pro | B11: Output | C11: How is the output used for other system component(s)? | D11: The model's predictions are used to populate a 'What-If? Dashboard'. This dashboard allows users to modify patient features (like doctor recommendation or age) and immediately see how the predicted probability of vaccination changes. | E11: SMOG Index | F11: 14.555
A12: Gemini 3 Pro | B12: Output | C12: How should I best utilize the output of the system? | D12: Healthcare professionals can use the probability scores to identify individuals who are unlikely to be vaccinated (low probability scores). This allows for targeted educational interventions or discussions, particularly by focusing on modifiable factors like `doctor_recc_h1n1` (doctor's recommendation) which significantly influences the prediction. | E12: SMOG Index | F12: 20.737
A13: Gemini 3 Pro | B13: Output | C13: How should the output fit in my workflow? | D13: The output can be used during patient consultations or public health planning to triage resources. For example, knowing that a doctor's recommendation is a top factor, a clinician can use the 'What-If' dashboard to simulate the impact of recommending the vaccine to a hesitant patient, visually demonstrating the potential increase in their likelihood of uptake. | E13: SMOG Index | F13: 17.122
A14: Gemini 3 Pro | B14: Output | C14: What is the source of the information object(s)? | D14: The information comes from the trained XGBoost model, which learned patterns from the NHFS dataset. Specific patient predictions are generated by applying this model to the input features provided for that patient. | E14: SMOG Index | F14: 13.024
A15: Gemini 3 Pro | B15: Output | C15: What is the scope of the output data? | D15: The output data is scoped to the individual level. The system generates a prediction for each single respondent or patient profile processed. | E15: SMOG Index | F15: 11.208
A16: Gemini 3 Pro | B16: Output | C16: What is the amount of the output data? | D16: For every patient profile input, the system returns a single probability score and a single binary classification label. | E16: SMOG Index | F16: 14.555
A17: Gemini 3 Pro | B17: Output | C17: What logic is used for the initial output/recommendation? | D17: The system applies a threshold of 0.5 to the predicted probability. If the probability is greater than or equal to 0.5, it predicts 'Yes' (1); otherwise, it predicts 'No' (0). | E17: SMOG Index | F17: 8.842
A18: Gemini 3 Pro | B18: Performance | C18: How accurate/precise/reliable are the predictions? | D18: The system has an overall accuracy of 84%. However, for predicting the vaccinated class (class 1), the precision is 68% and recall is 46%, meaning it is more reliable when it predicts 'Yes' than it is at catching all 'Yes' cases. | E18: SMOG Index | F18: 13.817
A19: Gemini 3 Pro | B19: Performance | C19: How often does the system make mistakes? | D19: The system makes a mistake in approximately 16% of cases (accuracy is 0.84). In the test set of 5,342 people, it misclassified 250 unvaccinated people as vaccinated and 606 vaccinated people as unvaccinated. | E19: SMOG Index | F19: 13.817
... A433: Claude Opus 4.6 Reasoning | B433: UI | C433: What does this UI element do? | D433: The system's interface includes several key visual elements: variable importance bar charts display features ranked by their impact on model performance (measured by dropout loss — higher values indicate greater importance); partial dependence profile plots show how the average predicted probability changes as a single feature varies across its range, helping users understand the direction and magnitude of each feature's effect; accumulated local effects plots provide a similar view but account for correlations between features, offering a more robust interpretation; break-down plots decompose an individual prediction into positive and negative contributions from each feature, showing which factors pushed the prediction higher or lower; and the what-if dashboard presents an interactive scatter plot where users can select individual data points, modify their feature values, and observe real-time changes in predicted probabilities. | E433: Flesch Kincaid Grade | F433: 58.32
A434: Human | B434: Data | C434: What kind of data was the system trained on? | E434: SMOG Index | F434: 13.024
A435: Human | B435: Data | C435: What is the source of the training data? | E435: SMOG Index | F435: 15.903
A436: Human | B436: Data | C436: How were the labels/ground-truth produced? | E436: SMOG Index | F436: 13.024
A437: Human | B437: Data | C437: What is the sample size of the training data? | E437: SMOG Index | F437: 6.427
A438: Human | B438: Data | C438: What dataset(s) is the system NOT using? | E438: SMOG Index | F438: 13.024
A439: Human | B439: Data | C439: What are the potential limitations/biases of the data? | E439: SMOG Index | F439: 15.58
A440: Human | B440: Output | C440: What kind of output does the system give? | E440: SMOG Index | F440: 13.428
A441: Human | B441: Output | C441: What does the system output mean? | E441: SMOG Index | F441: 14.868
A442: Human | B442: Output | C442: What is the scope of the system's capability? Can it do...? | E442: SMOG Index | F442: 15.248
A443: Human | B443: Output | C443: How is the output used for other system component(s)? | E443: SMOG Index | F443: 14.906
A444: Human | B444: Output | C444: How should I best utilize the output of the system? | E444: SMOG Index | F444: 19.287
A445: Human | B445: Output | C445: How should the output fit in my workflow? | E445: SMOG Index | F445: 15.903
... A577: Human | B577: UI | C577: What does this UI element do? | E577: Flesch Kincaid Grade | F577: 10.555
H588: =14.61-14.77 -> -0.16

Sheet Q Interpretation
A1: Run | B1: Model | C1: Category | D1: Question | E1: BERT Precision | F1: BERT Recall | G1: BERT F1 | H1: SBERT | I1: LLM Interpretation | J1: Human Interpretation | L1: Similarity Score
A2: Run 3 | B2: Claude Opus 4.6 Reasoning | C2: Data | D2: How were the labels/ground-truth produced? | E2: 0.842 | F2: 0.885 | G2: 0.863 | H2: 0.108 | I2: How was the 'correct answer' — whether someone received the H1N1 vaccine — determined? This matters because the reliability of the ground truth directly affects how trustworthy the system's predictions are. | J2: Where have the target variables come from? How were they created? | L2: {=INDEX('ACF Scores'!M:M, MATCH(1, (B2='ACF Scores'!B:B)*(D2='ACF Scores'!D:D),0))} -> 0.73
A3: Run 1 | B3: Gemini 3 Pro | C3: How (global model-wide explanation) | D3: What kind of rules does it follow? | E3: 0.867 | F3: 0.914 | G3: 0.89 | H3: 0.151 | I3: Are there explicit rules I can see? | J3: What is the workflow of the system? | L3: {=INDEX('ACF Scores'!M:M, MATCH(1, (B3='ACF Scores'!B:B)*(D3='ACF Scores'!D:D),0))} -> 0.477
A4: Run 3 | B4: Claude Opus 4.6 Reasoning | C4: Performance | D4: How accurate/precise/reliable are the predictions? | E4: 0.848 | F4: 0.886 | G4: 0.867 | H4: 0.153 | I4: How well does the system distinguish between individuals who did and did not receive the H1N1 vaccine? This is fundamental for determining whether the system's predictions can be trusted for public health decision-making. | J4: How is the system evaluated? What are key performance metrics? | L4: {=INDEX('ACF Scores'!M:M, MATCH(1, (B4='ACF Scores'!B:B)*(D4='ACF Scores'!D:D),0))} -> 0.577
A5: Run 2 | B5: ChatGPT 5.2 Extended Thinking | C5: How (global model-wide explanation) | D5: What is the system's overall logic? | E5: 0.842 | F5: 0.871 | G5: 0.856 | H5: 0.17 | I5: This asks for the model's 'clinical reasoning' in plain terms—what patterns it is using—so clinicians can judge whether they are plausible and ethically acceptable. | J5: What is the aim/objective of the system? | L5: {=INDEX('ACF Scores'!M:M, MATCH(1, (B5='ACF Scores'!B:B)*(D5='ACF Scores'!D:D),0))} -> 0.636
A6: Run 3 | B6: Claude Opus 4.6 Reasoning | C6: Output | D6: How should I best utilize the output of the system? | E6: 0.884 | F6: 0.927 | G6: 0.905 | H6: 0.17 | I6: What is the recommended way for a healthcare professional to use the system's predictions in practice? This guidance helps ensure safe and effective use. | J6: How can the output be used practically and effectively? | L6: {=INDEX('ACF Scores'!M:M, MATCH(1, (B6='ACF Scores'!B:B)*(D6='ACF Scores'!D:D),0))} -> 0.68
A7: Run 1 | B7: Gemini 3 Pro | C7: Performance | D7: In what situations is the system likely to be correct/incorrect? | E7: 0.877 | F7: 0.898 | G7: 0.888 | H7: 0.176 | I7: Are there specific cases where the AI is stronger or weaker? | J7: What conditions cause the system to make mistakes? | L7: {=INDEX('ACF Scores'!M:M, MATCH(1, (B7='ACF Scores'!B:B)*(D7='ACF Scores'!D:D),0))} -> 0.73
A8: Run 2 | B8: ChatGPT 5.2 Extended Thinking | C8: How (global model-wide explanation) | D8: What features does the system consider? | E8: 0.848 | F8: 0.88 | G8: 0.864 | H8: 0.186 | I8: This asks which patient/respondent characteristics the model looks at, which matters for data collection burden, interpretability, and assessing whether any important clinical factors are missing. | J8: What part of the input data is the system using to generate predictions? | L8: {=INDEX('ACF Scores'!M:M, MATCH(1, (B8='ACF Scores'!B:B)*(D8='ACF Scores'!D:D),0))} -> 0.74
A9: Run 1 | B9: Gemini 3 Pro | C9: Others | D9: What are the results of other people using the system? | E9: 0.918 | F9: 0.898 | G9: 0.908 | H9: 0.21 | I9: Has this been validated by others? | J9: Are you able to see how the system is being used by other people? Does this change the system? | L9: {=INDEX('ACF Scores'!M:M, MATCH(1, (B9='ACF Scores'!B:B)*(D9='ACF Scores'!D:D),0))} -> 0.352
A10: Run 1 | B10: Gemini 3 Pro | C10: Others | D10: Who is responsible for this system? Who are the authors? | E10: 0.877 | F10: 0.901 | G10: 0.889 | H10: 0.217 | I10: Who built this AI? | J10: Background information on the system. | L10: {=INDEX('ACF Scores'!M:M, MATCH(1, (B10='ACF Scores'!B:B)*(D10='ACF Scores'!D:D),0))} -> 0.77
A11: Run 2 | B11: ChatGPT 5.2 Extended Thinking | C11: Data | D11: How were the labels/ground-truth produced? | E11: 0.851 | F11: 0.88 | G11: 0.865 | H11: 0.246 | I11: This is asking what the system treats as the 'correct answer' during training and how that reference standard was obtained, because label quality directly affects patient-safety risk. | J11: Where have the target variables come from? How were they created? | L11: {=INDEX('ACF Scores'!M:M, MATCH(1, (B11='ACF Scores'!B:B)*(D11='ACF Scores'!D:D),0))} -> 0.685
A12: Run 1 | B12: Gemini 3 Pro | C12: Output | D12: How should I best utilize the output of the system? | E12: 0.887 | F12: 0.897 | G12: 0.892 | H12: 0.248 | I12: How can this tool help me in a clinical or public health setting? | J12: How can the output be used practically and effectively? | L12: {=INDEX('ACF Scores'!M:M, MATCH(1, (B12='ACF Scores'!B:B)*(D12='ACF Scores'!D:D),0))} -> 0.584
A13: Run 1 | B13: Gemini 3 Pro | C13: Data | D13: How were the labels/ground-truth produced? | E13: 0.863 | F13: 0.887 | G13: 0.875 | H13: 0.258 | I13: How do we know if the prediction target (vaccination status) is actually true in the data? | J13: Where have the target variables come from? How were they created? | L13: {=INDEX('ACF Scores'!M:M, MATCH(1, (B13='ACF Scores'!B:B)*(D13='ACF Scores'!D:D),0))} -> 0.779
... A109: Run 1 | B109: Gemini 3 Pro | C109: Performance | D109: How often does the system make mistakes? | E109: 0.985 | F109: 0.969 | G109: 0.977 | H109: 0.882 | I109: What is the error rate? | J109: What is the error rate of the system? | L109: {=INDEX('ACF Scores'!M:M, MATCH(1, (B109='ACF Scores'!B:B)*(D109='ACF Scores'!D:D),0))} -> 0.599

Sheet Averages
B1: ACF
A2: {=_xlfn.UNIQUE('ACF Scores'!C:C)} -> Category | B2: ChatGPT 5.2 Extended Thinking | C2: Claude Opus 4.6 Reasoning | D2: Gemini 3 Pro
A3: How (global) | B3: =AVERAGEIFS('ACF Scores'!$O:$O,'ACF Scores'!$B:$B,Averages!B$2,'ACF Scores'!$C:$C,Averages!$A3) -> 0.70070833 | C3: =AVERAGEIFS('ACF Scores'!$O:$O,'ACF Scores'!$B:$B,Averages!C$2,'ACF Scores'!$C:$C,Averages!$A3) -> 0.70160417 | D3: =AVERAGEIFS('ACF Scores'!$O:$O,'ACF Scores'!$B:$B,Averages!D$2,'ACF Scores'!$C:$C,Averages!$A3) -> 0.66739583 | E3: =AVERAGE(B3:D3) -> 0.68990278
A4: Data | B4: =AVERAGEIFS('ACF Scores'!$O:$O,'ACF Scores'!$B:$B,Averages!B$2,'ACF Scores'!$C:$C,Averages!$A4) -> 0.71836111 | C4: =AVERAGEIFS('ACF Scores'!$O:$O,'ACF Scores'!$B:$B,Averages!C$2,'ACF Scores'!$C:$C,Averages!$A4) -> 0.77769444 | D4: =AVERAGEIFS('ACF Scores'!$O:$O,'ACF Scores'!$B:$B,Averages!D$2,'ACF Scores'!$C:$C,Averages!$A4) -> 0.78094444 | E4: =AVERAGE(B4:D4) -> 0.759
A5: Output | B5: =AVERAGEIFS('ACF Scores'!$O:$O,'ACF Scores'!$B:$B,Averages!B$2,'ACF Scores'!$C:$C,Averages!$A5) -> 0.68638333 | C5: =AVERAGEIFS('ACF Scores'!$O:$O,'ACF Scores'!$B:$B,Averages!C$2,'ACF Scores'!$C:$C,Averages!$A5) -> 0.64373333 | D5: =AVERAGEIFS('ACF Scores'!$O:$O,'ACF Scores'!$B:$B,Averages!D$2,'ACF Scores'!$C:$C,Averages!$A5) -> 0.56275 | E5: =AVERAGE(B5:D5) -> 0.63095556
A6: Others | B6: =AVERAGEIFS('ACF Scores'!$O:$O,'ACF Scores'!$B:$B,Averages!B$2,'ACF Scores'!$C:$C,Averages!$A6) -> 0.77276667 | C6: =AVERAGEIFS('ACF Scores'!$O:$O,'ACF Scores'!$B:$B,Averages!C$2,'ACF Scores'!$C:$C,Averages!$A6) -> 0.7955 | D6: =AVERAGEIFS('ACF Scores'!$O:$O,'ACF Scores'!$B:$B,Averages!D$2,'ACF Scores'!$C:$C,Averages!$A6) -> 0.73373333 | E6: =AVERAGE(B6:D6) -> 0.76733333
A7: Performance | B7: =AVERAGEIFS('ACF Scores'!$O:$O,'ACF Scores'!$B:$B,Averages!B$2,'ACF Scores'!$C:$C,Averages!$A7) -> 0.7393 | C7: =AVERAGEIFS('ACF Scores'!$O:$O,'ACF Scores'!$B:$B,Averages!C$2,'ACF Scores'!$C:$C,Averages!$A7) -> 0.6914 | D7: =AVERAGEIFS('ACF Scores'!$O:$O,'ACF Scores'!$B:$B,Averages!D$2,'ACF Scores'!$C:$C,Averages!$A7) -> 0.67426667 | E7: =AVERAGE(B7:D7) -> 0.70165556
A8: UI | B8: =AVERAGEIFS('ACF Scores'!$O:$O,'ACF Scores'!$B:$B,Averages!B$2,'ACF Scores'!$C:$C,Averages!$A8) -> 0.78733333 | C8: =AVERAGEIFS('ACF Scores'!$O:$O,'ACF Scores'!$B:$B,Averages!C$2,'ACF Scores'!$C:$C,Averages!$A8) -> 0.63141667 | D8: =AVERAGEIFS('ACF Scores'!$O:$O,'ACF Scores'!$B:$B,Averages!D$2,'ACF Scores'!$C:$C,Averages!$A8) -> 0.8165 | E8: =AVERAGE(B8:D8) -> 0.74508333
A9: 0
B11: Readability
A12: {=_xlfn.UNIQUE('Readability All Scores'!B:B)} -> Category | B12: ChatGPT 5.2 Extended Thinking | C12: Claude Opus 4.6 Reasoning | D12: Gemini 3 Pro
A13: Data | B13: =AVERAGEIFS('Readability All Scores'!$F:$F,'Readability All Scores'!$A:$A,Averages!B$12,'Readability All Scores'!$B:$B,Averages!$A13) -> 13.67375 | C13: =AVERAGEIFS('Readability All Scores'!$F:$F,'Readability All Scores'!$A:$A,Averages!C$12,'Readability All Scores'!$B:$B,Averages!$A13) -> 16.170833 | D13: =AVERAGEIFS('Readability All Scores'!$F:$F,'Readability All Scores'!$A:$A,Averages!D$12,'Readability All Scores'!$B:$B,Averages!$A13) -> 14.08675 | E13: =AVERAGE(B13:D13) -> 14.643778
A14: Output | B14: =AVERAGEIFS('Readability All Scores'!$F:$F,'Readability All Scores'!$A:$A,Averages!B$12,'Readability All Scores'!$B:$B,Averages!$A14) -> 15.723025 | C14: =AVERAGEIFS('Readability All Scores'!$F:$F,'Readability All Scores'!$A:$A,Averages!C$12,'Readability All Scores'!$B:$B,Averages!$A14) -> 16.012125 | D14: =AVERAGEIFS('Readability All Scores'!$F:$F,'Readability All Scores'!$A:$A,Averages!D$12,'Readability All Scores'!$B:$B,Averages!$A14) -> 13.54255 | E14: =AVERAGE(B14:D14) -> 15.092567
A15: Performance | B15: =AVERAGEIFS('Readability All Scores'!$F:$F,'Readability All Scores'!$A:$A,Averages!B$12,'Readability All Scores'!$B:$B,Averages!$A15) -> 13.464 | C15: =AVERAGEIFS('Readability All Scores'!$F:$F,'Readability All Scores'!$A:$A,Averages!C$12,'Readability All Scores'!$B:$B,Averages!$A15) -> 15.38815 | D15: =AVERAGEIFS('Readability All Scores'!$F:$F,'Readability All Scores'!$A:$A,Averages!D$12,'Readability All Scores'!$B:$B,Averages!$A15) -> 11.226 | E15: =AVERAGE(B15:D15) -> 13.359383
A16: How (global) | B16: =AVERAGEIFS('Readability All Scores'!$F:$F,'Readability All Scores'!$A:$A,Averages!B$12,'Readability All Scores'!$B:$B,Averages!$A16) -> 15.346656 | C16: =AVERAGEIFS('Readability All Scores'!$F:$F,'Readability All Scores'!$A:$A,Averages!C$12,'Readability All Scores'!$B:$B,Averages!$A16) -> 16.899031 | D16: =AVERAGEIFS('Readability All Scores'!$F:$F,'Readability All Scores'!$A:$A,Averages!D$12,'Readability All Scores'!$B:$B,Averages!$A16) -> 16.378063 | E16: =AVERAGE(B16:D16) -> 16.207917
A17: Others | B17: =AVERAGEIFS('Readability All Scores'!$F:$F,'Readability All Scores'!$A:$A,Averages!B$12,'Readability All Scores'!$B:$B,Averages!$A17) -> 14.2399 | C17: =AVERAGEIFS('Readability All Scores'!$F:$F,'Readability All Scores'!$A:$A,Averages!C$12,'Readability All Scores'!$B:$B,Averages!$A17) -> 15.31625 | D17: =AVERAGEIFS('Readability All Scores'!$F:$F,'Readability All Scores'!$A:$A,Averages!D$12,'Readability All Scores'!$B:$B,Averages!$A17) -> 13.271 | E17: =AVERAGE(B17:D17) -> 14.275717
A18: UI | B18: =AVERAGEIFS('Readability All Scores'!$F:$F,'Readability All Scores'!$A:$A,Averages!B$12,'Readability All Scores'!$B:$B,Averages!$A18) -> 16.0925 | C18: =AVERAGEIFS('Readability All Scores'!$F:$F,'Readability All Scores'!$A:$A,Averages!C$12,'Readability All Scores'!$B:$B,Averages!$A18) -> 27.914125 | D18: =AVERAGEIFS('Readability All Scores'!$F:$F,'Readability All Scores'!$A:$A,Averages!D$12,'Readability All Scores'!$B:$B,Averages!$A18) -> 10.87325 | E18: =AVERAGE(B18:D18) -> 18.293292
A19: How (global model-wide explanation)
A20: 0

Sheet Ranking
A1: Category | B1: Question | C1: Average ACF Score | D1: Rank | F1: Category | G1: Question | H1: Average Readability Score | I1: Rank | L1: Extended | M1: Index | N1: Category | O1: Question | P1: Avereage Score | Q1: Rank | R1: Average Score | S1: Rank
A2: Data | B2: What is the source of the training data? | C2: 0.90888889 | D2: 1 | F2: Others | G2: Does the system learn specifically from my interaction? | H2: 11.312667 | I2: 1 | J2: =INDEX(C:C,MATCH(G2,B:B,0)) -> 0.809 | M2: 1 | N2: =INDEX(F:F,MATCH(O2,G:G,0)) -> Data | O2: What is the source of the training data? | P2: =INDEX(C:C,MATCH(O2,B:B,0)) -> 0.90888889 | Q2: =INDEX(D:D,MATCH(O2,B:B,0)) -> 1 | R2: =INDEX(H:H,MATCH(O2,G:G,0)) -> 15.707167 | S2: =INDEX(I:I,MATCH(O2,G:G,0)) -> 24
A3: How (global) | B3: What kind of algorithm is used? | C3: 0.88922222 | D3: 2 | F3: Performance | G3: How accurate/precise/reliable are the predictions? | H3: 11.561583 | I3: 2 | J3: =INDEX(D:D,MATCH(G3,B:B,0)) -> 19 | M3: 2 | N3: =INDEX(F:F,MATCH(O3,G:G,0)) -> How (global) | O3: What kind of algorithm is used? | P3: =INDEX(C:C,MATCH(O3,B:B,0)) -> 0.88922222 | Q3: =INDEX(D:D,MATCH(O3,B:B,0)) -> 2 | R3: =INDEX(H:H,MATCH(O3,G:G,0)) -> 16.501583 | S3: =INDEX(I:I,MATCH(O3,G:G,0)) -> 27
A4: Others | B4: Who is responsible for this system? Who are the authors? | C4: 0.86788889 | D4: 3 | F4: Output | G4: What logic is used for the initial output/recommendation? | H4: 12.409083 | I4: 3 | J4: =INDEX(D:D,MATCH(G4,B:B,0)) -> 27 | L4: * | M4: 3 | N4: =INDEX(F:F,MATCH(O4,G:G,0)) -> Others | O4: Who is responsible for this system? Who are the authors? | P4: =INDEX(C:C,MATCH(O4,B:B,0)) -> 0.86788889 | Q4: =INDEX(D:D,MATCH(O4,B:B,0)) -> 3 | R4: =INDEX(H:H,MATCH(O4,G:G,0)) -> 14.9255 | S4: =INDEX(I:I,MATCH(O4,G:G,0)) -> 17
A5: How (global) | B5: What are the top rules/features that determine its predictions? | C5: 0.84722222 | D5: 4 | F5: Data | G5: What is the sample size of the training data? | H5: 12.422667 | I5: 4 | J5: =INDEX(D:D,MATCH(G5,B:B,0)) -> 24 | M5: 4 | N5: =INDEX(F:F,MATCH(O5,G:G,0)) -> How (global) | O5: What are the top rules/features that determine its predictions? | P5: =INDEX(C:C,MATCH(O5,B:B,0)) -> 0.84722222 | Q5: =INDEX(D:D,MATCH(O5,B:B,0)) -> 4 | R5: =INDEX(H:H,MATCH(O5,G:G,0)) -> 17.75475 | S5: =INDEX(I:I,MATCH(O5,G:G,0)) -> 34
A6: Data | B6: What kind of data was the system trained on? | C6: 0.83977778 | D6: 5 | F6: Performance | G6: What kind of mistakes is the system likely to make? | H6: 13.123 | I6: 5 | J6: =INDEX(D:D,MATCH(G6,B:B,0)) -> 10 | M6: 5 | N6: =INDEX(F:F,MATCH(O6,G:G,0)) -> Data | O6: What kind of data was the system trained on? | P6: =INDEX(C:C,MATCH(O6,B:B,0)) -> 0.83977778 | Q6: =INDEX(D:D,MATCH(O6,B:B,0)) -> 5 | R6: =INDEX(H:H,MATCH(O6,G:G,0)) -> 13.609333 | S6: =INDEX(I:I,MATCH(O6,G:G,0)) -> 9
A7: How (global) | B7: How does the system make predictions? | C7: 0.83522222 | D7: 6 | F7: Others | G7: How have updates affected the system? | H7: 13.126333 | I7: 6 | J7: =INDEX(D:D,MATCH(G7,B:B,0)) -> 21 | M7: 6 | N7: =INDEX(F:F,MATCH(O7,G:G,0)) -> How (global) | O7: How does the system make predictions? | P7: =INDEX(C:C,MATCH(O7,B:B,0)) -> 0.83522222 | Q7: =INDEX(D:D,MATCH(O7,B:B,0)) -> 6 | R7: =INDEX(H:H,MATCH(O7,G:G,0)) -> 15.550083 | S7: =INDEX(I:I,MATCH(O7,G:G,0)) -> 21
A8: Data | B8: How were the labels/ground-truth produced? | C8: 0.83066667 | D8: 7 | F8: Output | G8: What does the system output mean? | H8: 13.29375 | I8: 7 | J8: =INDEX(D:D,MATCH(G8,B:B,0)) -> 32 | M8: 7 | N8: =INDEX(F:F,MATCH(O8,G:G,0)) -> Data | O8: How were the labels/ground-truth produced? | P8: =INDEX(C:C,MATCH(O8,B:B,0)) -> 0.83066667 | Q8: =INDEX(D:D,MATCH(O8,B:B,0)) -> 7 | R8: =INDEX(H:H,MATCH(O8,G:G,0)) -> 13.6485 | S8: =INDEX(I:I,MATCH(O8,G:G,0)) -> 10
A9: Performance | B9: How often does the system make mistakes? | C9: 0.82722222 | D9: 8 | F9: Performance | G9: How often does the system make mistakes? | H9: 13.293917 | I9: 8 | J9: =INDEX(D:D,MATCH(G9,B:B,0)) -> 8 | M9: 8 | N9: =INDEX(F:F,MATCH(O9,G:G,0)) -> Performance | O9: How often does the system make mistakes? | P9: =INDEX(C:C,MATCH(O9,B:B,0)) -> 0.82722222 | Q9: =INDEX(D:D,MATCH(O9,B:B,0)) -> 8 | R9: =INDEX(H:H,MATCH(O9,G:G,0)) -> 13.293917 | S9: =INDEX(I:I,MATCH(O9,G:G,0)) -> 8
A10: Others | B10: Does the system learn specifically from my interaction? | C10: 0.809 | D10: 9 | F10: Data | G10: What kind of data was the system trained on? | H10: 13.609333 | I10: 9 | J10: =INDEX(D:D,MATCH(G10,B:B,0)) -> 5 | L10: * | M10: 9 | N10: =INDEX(F:F,MATCH(O10,G:G,0)) -> Others | O10: Does the system learn specifically from my interaction? | P10: =INDEX(C:C,MATCH(O10,B:B,0)) -> 0.809 | Q10: =INDEX(D:D,MATCH(O10,B:B,0)) -> 9 | R10: =INDEX(H:H,MATCH(O10,G:G,0)) -> 11.312667 | S10: =INDEX(I:I,MATCH(O10,G:G,0)) -> 1
A11: Performance | B11: What kind of mistakes is the system likely to make? | C11: 0.79961111 | D11: 10 | F11: Data | G11: How were the labels/ground-truth produced? | H11: 13.6485 | I11: 10 | J11: =INDEX(D:D,MATCH(G11,B:B,0)) -> 7 | M11: 10 | N11: =INDEX(F:F,MATCH(O11,G:G,0)) -> Performance | O11: What kind of mistakes is the system likely to make? | P11: =INDEX(C:C,MATCH(O11,B:B,0)) -> 0.79961111 | Q11: =INDEX(D:D,MATCH(O11,B:B,0)) -> 10 | R11: =INDEX(H:H,MATCH(O11,G:G,0)) -> 13.123 | S11: =INDEX(I:I,MATCH(O11,G:G,0)) -> 5
A12: How (global) | B12: What features does the system consider? | C12: 0.77627778 | D12: 11 | F12: Output | G12: What is the scope of the output data? | H12: 13.9685 | I12: 11 | J12: =INDEX(D:D,MATCH(G12,B:B,0)) -> 25 | M12: 11 | N12: =INDEX(F:F,MATCH(O12,G:G,0)) -> How (global) | O12: What features does the system consider? | P12: =INDEX(C:C,MATCH(O12,B:B,0)) -> 0.77627778 | Q12: =INDEX(D:D,MATCH(O12,B:B,0)) -> 11 | R12: =INDEX(H:H,MATCH(O12,G:G,0)) -> 19.13875 | S12: =INDEX(I:I,MATCH(O12,G:G,0)) -> 35
A13: UI | B13: What are the affordances of the system? | C13: 0.77322222 | D13: 12 | F13: How (global) | G13: What kind of rules does it follow? | H13: 14.201833 | I13: 12 | J13: =INDEX(D:D,MATCH(G13,B:B,0)) -> 33 | L13: * | M13: 12 | N13: =INDEX(F:F,MATCH(O13,G:G,0)) -> UI | O13: What are the affordances of the system? | P13: =INDEX(C:C,MATCH(O13,B:B,0)) -> 0.77322222 | Q13: =INDEX(D:D,MATCH(O13,B:B,0)) -> 12 | R13: =INDEX(H:H,MATCH(O13,G:G,0)) -> 16.79575 | S13: =INDEX(I:I,MATCH(O13,G:G,0)) -> 32
A14: How (global) | B14: How were the parameters set? | C14: 0.74755556 | D14: 13 | F14: Performance | G14: In what situations is the system likely to be correct/incorrect? | H14: 14.36625 | I14: 13 | J14: =INDEX(D:D,MATCH(G14,B:B,0)) -> 22 | M14: 13 | N14: =INDEX(F:F,MATCH(O14,G:G,0)) -> How (global) | O14: How were the parameters set? | P14: =INDEX(C:C,MATCH(O14,B:B,0)) -> 0.74755556 | Q14: =INDEX(D:D,MATCH(O14,B:B,0)) -> 13 | R14: =INDEX(H:H,MATCH(O14,G:G,0)) -> 15.182 | S14: =INDEX(I:I,MATCH(O14,G:G,0)) -> 18
A15: Others | B15: Why is the system using or not using a given algorithm/feature/rule/dataset? | C15: 0.74638889 | D15: 14 | F15: Performance | G15: What are the limitations of the system? | H15: 14.452167 | I15: 14 | J15: =INDEX(D:D,MATCH(G15,B:B,0)) -> 34 | M15: 14 | N15: =INDEX(F:F,MATCH(O15,G:G,0)) -> Others | O15: Why is the system using or not using a given algorithm/feature/rule/dataset? | P15: =INDEX(C:C,MATCH(O15,B:B,0)) -> 0.74638889 | Q15: =INDEX(D:D,MATCH(O15,B:B,0)) -> 14 | R15: =INDEX(H:H,MATCH(O15,G:G,0)) -> 16.535667 | S15: =INDEX(I:I,MATCH(O15,G:G,0)) -> 28
A16: Output | B16: How should the output fit in my workflow? | C16: 0.72733333 | D16: 15 | F16: Output | G16: What kind of output does the system give? | H16: 14.580667 | I16: 15 | J16: =INDEX(D:D,MATCH(G16,B:B,0)) -> 31 | M16: 15 | N16: =INDEX(F:F,MATCH(O16,G:G,0)) -> Output | O16: How should the output fit in my workflow? | P16: =INDEX(C:C,MATCH(O16,B:B,0)) -> 0.72733333 | Q16: =INDEX(D:D,MATCH(O16,B:B,0)) -> 15 | R16: =INDEX(H:H,MATCH(O16,G:G,0)) -> 15.56875 | S16: =INDEX(I:I,MATCH(O16,G:G,0)) -> 22
A17: Others | B17: What are the results of other people using the system? | C17: 0.72333333 | D17: 16 | F17: Output | G17: What is the scope of the system's capability? Can it do...? | H17: 14.824167 | I17: 16 | J17: =INDEX(D:D,MATCH(G17,B:B,0)) -> 30 | M17: 16 | N17: =INDEX(F:F,MATCH(O17,G:G,0)) -> Others | O17: What are the results of other people using the system? | P17: =INDEX(C:C,MATCH(O17,B:B,0)) -> 0.72333333 | Q17: =INDEX(D:D,MATCH(O17,B:B,0)) -> 16 | R17: =INDEX(H:H,MATCH(O17,G:G,0)) -> 15.478417 | S17: =INDEX(I:I,MATCH(O17,G:G,0)) -> 20
A18: Output | B18: What is the source of the information object(s)? | C18: 0.71905556 | D18: 17 | F18: Others | G18: Who is responsible for this system? Who are the authors? | H18: 14.9255 | I18: 17 | J18: =INDEX(D:D,MATCH(G18,B:B,0)) -> 3 | L18: * | M18: 17 | N18: =INDEX(F:F,MATCH(O18,G:G,0)) -> Output | O18: What is the source of the information object(s)? | P18: =INDEX(C:C,MATCH(O18,B:B,0)) -> 0.71905556 | Q18: =INDEX(D:D,MATCH(O18,B:B,0)) -> 17 | R18: =INDEX(H:H,MATCH(O18,G:G,0)) -> 15.386417 | S18: =INDEX(I:I,MATCH(O18,G:G,0)) -> 19
A19: UI | B19: What does this UI element do? | C19: 0.71694444 | D19: 18 | F19: How (global) | G19: How were the parameters set? | H19: 15.182 | I19: 18 | J19: =INDEX(D:D,MATCH(G19,B:B,0)) -> 13 | M19: 18 | N19: =INDEX(F:F,MATCH(O19,G:G,0)) -> UI | O19: What does this UI element do? | P19: =INDEX(C:C,MATCH(O19,B:B,0)) -> 0.71694444 | Q19: =INDEX(D:D,MATCH(O19,B:B,0)) -> 18 | R19: =INDEX(H:H,MATCH(O19,G:G,0)) -> 19.790833 | S19: =INDEX(I:I,MATCH(O19,G:G,0)) -> 36
A20: Performance | B20: How accurate/precise/reliable are the predictions? | C20: 0.69705556 | D20: 19 | F20: Output | G20: What is the source of the information object(s)? | H20: 15.386417 | I20: 19 | J20: =INDEX(D:D,MATCH(G20,B:B,0)) -> 17 | M20: 19 | N20: =INDEX(F:F,MATCH(O20,G:G,0)) -> Performance | O20: How accurate/precise/reliable are the predictions? | P20: =INDEX(C:C,MATCH(O20,B:B,0)) -> 0.69705556 | Q20: =INDEX(D:D,MATCH(O20,B:B,0)) -> 19 | R20: =INDEX(H:H,MATCH(O20,G:G,0)) -> 11.561583 | S20: =INDEX(I:I,MATCH(O20,G:G,0)) -> 2
A21: Data | B21: What are the potential limitations/biases of the data? | C21: 0.695 | D21: 20 | F21: Others | G21: What are the results of other people using the system? | H21: 15.478417 | I21: 20 | J21: =INDEX(D:D,MATCH(G21,B:B,0)) -> 16 | M21: 20 | N21: =INDEX(F:F,MATCH(O21,G:G,0)) -> Data | O21: What are the potential limitations/biases of the data? | P21: =INDEX(C:C,MATCH(O21,B:B,0)) -> 0.695 | Q21: =INDEX(D:D,MATCH(O21,B:B,0)) -> 20 | R21: =INDEX(H:H,MATCH(O21,G:G,0)) -> 15.82775 | S21: =INDEX(I:I,MATCH(O21,G:G,0)) -> 26
A22: Others | B22: How have updates affected the system? | C22: 0.69005556 | D22: 21 | F22: How (global) | G22: How does the system make predictions? | H22: 15.550083 | I22: 21 | J22: =INDEX(D:D,MATCH(G22,B:B,0)) -> 6 | L22: * | M22: 21 | N22: =INDEX(F:F,MATCH(O22,G:G,0)) -> Others | O22: How have updates affected the system? | P22: =INDEX(C:C,MATCH(O22,B:B,0)) -> 0.69005556 | Q22: =INDEX(D:D,MATCH(O22,B:B,0)) -> 21 | R22: =INDEX(H:H,MATCH(O22,G:G,0)) -> 13.126333 | S22: =INDEX(I:I,MATCH(O22,G:G,0)) -> 6
A23: Performance | B23: In what situations is the system likely to be correct/incorrect? | C23: 0.68844444 | D23: 22 | F23: Output | G23: How should the output fit in my workflow? | H23: 15.56875 | I23: 22 | J23: =INDEX(D:D,MATCH(G23,B:B,0)) -> 15 | M23: 22 | N23: =INDEX(F:F,MATCH(O23,G:G,0)) -> Performance | O23: In what situations is the system likely to be correct/incorrect? | P23: =INDEX(C:C,MATCH(O23,B:B,0)) -> 0.68844444 | Q23: =INDEX(D:D,MATCH(O23,B:B,0)) -> 22 | R23: =INDEX(H:H,MATCH(O23,G:G,0)) -> 14.36625 | S23: =INDEX(I:I,MATCH(O23,G:G,0)) -> 13
A24: Output | B24: How is the output used for other system component(s)? | C24: 0.67916667 | D24: 23 | F24: How (global) | G24: How does it weigh different features? | H24: 15.615417 | I24: 23 | J24: =INDEX(D:D,MATCH(G24,B:B,0)) -> 36 | M24: 23 | N24: =INDEX(F:F,MATCH(O24,G:G,0)) -> Output | O24: How is the output used for other system component(s)? | P24: =INDEX(C:C,MATCH(O24,B:B,0)) -> 0.67916667 | Q24: =INDEX(D:D,MATCH(O24,B:B,0)) -> 23 | R24: =INDEX(H:H,MATCH(O24,G:G,0)) -> 16.77125 | S24: =INDEX(I:I,MATCH(O24,G:G,0)) -> 31
A25: Data | B25: What is the sample size of the training data? | C25: 0.666 | D25: 24 | F25: Data | G25: What is the source of the training data? | H25: 15.707167 | I25: 24 | J25: =INDEX(D:D,MATCH(G25,B:B,0)) -> 1 | M25: 24 | N25: =INDEX(F:F,MATCH(O25,G:G,0)) -> Data | O25: What is the sample size of the training data? | P25: =INDEX(C:C,MATCH(O25,B:B,0)) -> 0.666 | Q25: =INDEX(D:D,MATCH(O25,B:B,0)) -> 24 | R25: =INDEX(H:H,MATCH(O25,G:G,0)) -> 12.422667 | S25: =INDEX(I:I,MATCH(O25,G:G,0)) -> 4
A26: Output | B26: What is the scope of the output data? | C26: 0.66038889 | D26: 25 | F26: How (global) | G26: What is the system's overall logic? | H26: 15.718917 | I26: 25 | J26: =INDEX(D:D,MATCH(G26,B:B,0)) -> 35 | L26: * | M26: 25 | N26: =INDEX(F:F,MATCH(O26,G:G,0)) -> Output | O26: What is the scope of the output data? | P26: =INDEX(C:C,MATCH(O26,B:B,0)) -> 0.66038889 | Q26: =INDEX(D:D,MATCH(O26,B:B,0)) -> 25 | R26: =INDEX(H:H,MATCH(O26,G:G,0)) -> 13.9685 | S26: =INDEX(I:I,MATCH(O26,G:G,0)) -> 11
A27: Output | B27: How should I best utilize the output of the system? | C27: 0.648 | D27: 26 | F27: Data | G27: What are the potential limitations/biases of the data? | H27: 15.82775 | I27: 26 | J27: =INDEX(D:D,MATCH(G27,B:B,0)) -> 20 | M27: 26 | N27: =INDEX(F:F,MATCH(O27,G:G,0)) -> Output | O27: How should I best utilize the output of the system? | P27: =INDEX(C:C,MATCH(O27,B:B,0)) -> 0.648 | Q27: =INDEX(D:D,MATCH(O27,B:B,0)) -> 26 | R27: =INDEX(H:H,MATCH(O27,G:G,0)) -> 17.376167 | S27: =INDEX(I:I,MATCH(O27,G:G,0)) -> 33
A28: Output | B28: What logic is used for the initial output/recommendation? | C28: 0.64327778 | D28: 27 | F28: How (global) | G28: What kind of algorithm is used? | H28: 16.501583 | I28: 27 | J28: =INDEX(D:D,MATCH(G28,B:B,0)) -> 2 | L28: * | M28: 27 | N28: =INDEX(F:F,MATCH(O28,G:G,0)) -> Output | O28: What logic is used for the initial output/recommendation? | P28: =INDEX(C:C,MATCH(O28,B:B,0)) -> 0.64327778 | Q28: =INDEX(D:D,MATCH(O28,B:B,0)) -> 27 | R28: =INDEX(H:H,MATCH(O28,G:G,0)) -> 12.409083 | S28: =INDEX(I:I,MATCH(O28,G:G,0)) -> 3
A29: Output | B29: What is the amount of the output data? | C29: 0.63294444 | D29: 28 | F29: Others | G29: Why is the system using or not using a given algorithm/feature/rule/dataset? | H29: 16.535667 | I29: 28 | J29: =INDEX(D:D,MATCH(G29,B:B,0)) -> 14 | L29: * | M29: 28 | N29: =INDEX(F:F,MATCH(O29,G:G,0)) -> Output | O29: What is the amount of the output data? | P29: =INDEX(C:C,MATCH(O29,B:B,0)) -> 0.63294444 | Q29: =INDEX(D:D,MATCH(O29,B:B,0)) -> 28 | R29: =INDEX(H:H,MATCH(O29,G:G,0)) -> 16.746917 | S29: =INDEX(I:I,MATCH(O29,G:G,0)) -> 30
A30: Data | B30: What dataset(s) is the system NOT using? | C30: 0.61366667 | D30: 29 | F30: Data | G30: What dataset(s) is the system NOT using? | H30: 16.64725 | I30: 29 | J30: =INDEX(D:D,MATCH(G30,B:B,0)) -> 29 | M30: 29 | N30: =INDEX(F:F,MATCH(O30,G:G,0)) -> Data | O30: What dataset(s) is the system NOT using? | P30: =INDEX(C:C,MATCH(O30,B:B,0)) -> 0.61366667 | Q30: =INDEX(D:D,MATCH(O30,B:B,0)) -> 29 | R30: =INDEX(H:H,MATCH(O30,G:G,0)) -> 16.64725 | S30: =INDEX(I:I,MATCH(O30,G:G,0)) -> 29
A31: Output | B31: What is the scope of the system's capability? Can it do...? | C31: 0.54783333 | D31: 30 | F31: Output | G31: What is the amount of the output data? | H31: 16.746917 | I31: 30 | J31: =INDEX(D:D,MATCH(G31,B:B,0)) -> 28 | M31: 30 | N31: =INDEX(F:F,MATCH(O31,G:G,0)) -> Output | O31: What is the scope of the system's capability? Can it do...? | P31: =INDEX(C:C,MATCH(O31,B:B,0)) -> 0.54783333 | Q31: =INDEX(D:D,MATCH(O31,B:B,0)) -> 30 | R31: =INDEX(H:H,MATCH(O31,G:G,0)) -> 14.824167 | S31: =INDEX(I:I,MATCH(O31,G:G,0)) -> 16
A32: Output | B32: What kind of output does the system give? | C32: 0.52794444 | D32: 31 | F32: Output | G32: How is the output used for other system component(s)? | H32: 16.77125 | I32: 31 | J32: =INDEX(D:D,MATCH(G32,B:B,0)) -> 23 | M32: 31 | N32: =INDEX(F:F,MATCH(O32,G:G,0)) -> Output | O32: What kind of output does the system give? | P32: =INDEX(C:C,MATCH(O32,B:B,0)) -> 0.52794444 | Q32: =INDEX(D:D,MATCH(O32,B:B,0)) -> 31 | R32: =INDEX(H:H,MATCH(O32,G:G,0)) -> 14.580667 | S32: =INDEX(I:I,MATCH(O32,G:G,0)) -> 15
A33: Output | B33: What does the system output mean? | C33: 0.52361111 | D33: 32 | F33: UI | G33: What are the affordances of the system? | H33: 16.79575 | I33: 32 | J33: =INDEX(D:D,MATCH(G33,B:B,0)) -> 12 | M33: 32 | N33: =INDEX(F:F,MATCH(O33,G:G,0)) -> Output | O33: What does the system output mean? | P33: =INDEX(C:C,MATCH(O33,B:B,0)) -> 0.52361111 | Q33: =INDEX(D:D,MATCH(O33,B:B,0)) -> 32 | R33: =INDEX(H:H,MATCH(O33,G:G,0)) -> 13.29375 | S33: =INDEX(I:I,MATCH(O33,G:G,0)) -> 7
